Workbook

Sheet Feed WACC
A2: Pellet size | B2: Protein | C2: Fat | D2: Mix | E2: SK CnF | F2: SK WACC | G2: AD CnF | H2: AD WACC | I2: GR
A3: 1.5mm | B3: 50 | C3: 14 | D3: 0.01 | E3: 1.82 | F3: =+D3*E3 -> 0.0182 | G3: 1.653 | H3: =+G3*D3 -> 0.01653
A4: 2mm | B4: 50 | C4: 14 | D4: 0.01 | E4: 1.66 | F4: =+D4*E4 -> 0.0166 | G4: 1.614 | H4: =+G4*D4 -> 0.01614
A5: 3mm | B5: 50 | C5: 14 | D5: 0.04 | E5: 1.66 | F5: =+D5*E5 -> 0.0664 | G5: 1.614 | H5: =+G5*D5 -> 0.06456
A6: 5mm | B6: 45 | C6: 14 | D6: 0.05 | E6: 1.38 | F6: =+D6*E6 -> 0.069 | G6: 1.491 | H6: =+G6*D6 -> 0.07455
A7: 7mm | B7: 45 | C7: 14 | D7: 0.4 | E7: 1.35 | F7: =+D7*E7 -> 0.54 | G7: 1.491 | H7: =+G7*D7 -> 0.5964
A8: 10mm | B8: 42 | C8: 14 | D8: 0.5 | E8: 1.29 | F8: =+D8*E8 -> 0.645 | G8: 1.449 | H8: =+G8*D8 -> 0.7245
F9: =SUM(F3:F8) -> 1.3552 | H9: =SUM(H3:H8) -> 1.49268

Sheet Assumptions (Domestic)
A1: Barramundi Costing & Pricing — DOMESTIC (Sri Lanka · LKR)
A2: SINGLE SOURCE OF TRUTH for farm costs. Edit yellow cells. Feed, clearing, FCR & ODC entered here are inherited by the Export tab — enter them ONCE.
E3: WHOLE-FISH COST BY SIZE BUCKET (g — median shown; only FCR & ODC vary by size)
A4: 1. BASE FISH COST (whole fish, ex-farm) | E4: 0–600 g med 300 | F4: 600–800 g med 700 | G4: 800–1100 g med 950 | H4: 1100–1500 g med 1300 | I4: 1500–1800 g med 1650 | J4: 1800–2200 g med 2000 | K4: 2200–4000 g med 3100
A5: Feed cost/kg | B5: 1.35 | C5: USD per kg of feed | D5: Median (g) → | E5: 300 | F5: 700 | G5: 950 | H5: 1300 | I5: 1650 | J5: 2000 | K5: 3100
A6: Clearing cost/kg | B6: 0.05 | C6: USD/kg — customs clearing / handling on imported feed
A7: Import tax on feed | B7: 0.35 | C7: % duty / levies on imported feed
A8: Effective feed cost | B8: =B5*(1+B7)+B6 -> 1.8725 | C8: USD/kg feed incl. import tax + clearing
A9: FCR (feed conversion ratio) | B9: 1.5 | C9: kg feed per kg live fish | D9: per-bucket → | E9: 1.1 | F9: 1.25 | G9: 1.35 | H9: 1.45 | I9: 1.55 | J9: 1.65 | K9: 1.75
A10: Feed cost per kg of fish | B10: =B8*B9 -> 2.80875 | C10: USD/kg live fish
A11: ODC — other direct costs (= sum below) | B11: =SUM(D12:D17) -> 0.42470588 | C11: USD/kg — auto-sum of components ▼ | D11: per-bucket → | E11: =($D$13+$D$14+$D$16+$D$17)+($D$12+$D$15)/(E5/1000) -> 1.1686275 | F11: =($D$13+$D$14+$D$16+$D$17)+($D$12+$D$15)/(F5/1000) -> 0.56134454 | G11: =($D$13+$D$14+$D$16+$D$17)+($D$12+$D$15)/(G5/1000) -> 0.44148607 | H11: =($D$13+$D$14+$D$16+$D$17)+($D$12+$D$15)/(H5/1000) -> 0.35113122 | I11: =($D$13+$D$14+$D$16+$D$17)+($D$12+$D$15)/(I5/1000) -> 0.29910873 | J11: =($D$13+$D$14+$D$16+$D$17)+($D$12+$D$15)/(J5/1000) -> 0.26529412 | K11: =($D$13+$D$14+$D$16+$D$17)+($D$12+$D$15)/(K5/1000) -> 0.20872865
A12: - fingerling cost | B12: 0.25 | C12: USD | D12: =IF(C12="USD",B12,B12/$B$20) -> 0.25
A13: - transport - trinco/colombo | B13: 19 | C13: LKR | D13: =IF(C13="USD",B13,B13/$B$20) -> 0.055882353
A14: - ice | B14: 12 | C14: LKR | D14: =IF(C14="USD",B14,B14/$B$20) -> 0.035294118
A15: - vaccine | B15: =17.55/0.75 -> 23.4 | C15: LKR | D15: =IF(C15="USD",B15,B15/$B$20) -> 0.068823529
A16: - additives | B16: 0 | C16: USD | D16: =IF(C16="USD",B16,B16/$B$20) -> 0
A17: - royalty | B17: 5 | C17: LKR | D17: =IF(C17="USD",B17,B17/$B$20) -> 0.014705882
A18: (fingerling→additives are PLACEHOLDER USD estimates — replace with real figures; royalty is your 5 LKR)
A19: Whole fish cost | B19: =B10+B11 -> 3.2334559 | C19: USD/kg live / whole fish | D19: per-bucket → | E19: =$B$8*E9+E11 -> 3.2283775 | F19: =$B$8*F9+F11 -> 2.9019695 | G19: =$B$8*G9+G11 -> 2.9693611 | H19: =$B$8*H9+H11 -> 3.0662562 | I19: =$B$8*I9+I11 -> 3.2014837 | J19: =$B$8*J9+J11 -> 3.3549191 | K19: =$B$8*K9+K11 -> 3.4856037
A20: FX rate | B20: 340 | C20: LKR per 1 USD ◄ drives all USD costs on SKU tab
A21: Whole fish cost | B21: =B19*B20 -> 1099.375 | C21: LKR/kg ◄ feeds SKU tab | D21: per-bucket → | E21: =E19*$B$20 -> 1097.6483 | F21: =F19*$B$20 -> 986.66964 | G21: =G19*$B$20 -> 1009.5828 | H21: =H19*$B$20 -> 1042.5271 | I21: =I19*$B$20 -> 1088.5045 | J21: =J19*$B$20 -> 1140.6725 | K21: =K19*$B$20 -> 1185.1052
A22: Size buckets: FCR (row 9, placeholder — replace with farm data) rises with size; ODC (row 11) now AUTO-amortises by median size — per-fish costs (fingerling + vaccine) divide by median weight, per-kg costs (transport, ice, additives, royalty) stay flat. Column B = ~1000g reference.
A23: 2. COMMON PER-KG ADDERS (LKR/kg)
A24: Transport | B24: 60 | C24: LKR/kg — default, overridable per SKU
A25: Freezer / cold holding | B25: 40 | C25: LKR/kg — default, overridable per SKU
A27: 3. STANDARD PRICE (rack rate)
A28: Retail / member / wholesale tiers are parked here until the subscription & pricing model returns.
A32: Domestic rack-rate margin (GM%) | B32: 0.4 | C32: standard price = FINAL ÷ (1 − this). Your domestic 'rack rate'.
A33: 4. SKU PORTFOLIO (live count from SKU Costing tab)
A34: Active SKUs | B34: =COUNTIF('SKU Costing (Domestic)'!$B$4:$B$37,"Active") -> 11 | C34: toggle Status on the SKU tab to change
A35: Inactive SKUs | B35: =COUNTIF('SKU Costing (Domestic)'!$B$4:$B$37,"Inactive") -> 23
A36: Total SKUs | B36: =B34+B35 -> 34
A38: LEGEND
A39: Yellow cell | B39: You edit this — an input / assumption
A40: Black number | B40: Calculated — do not overtype
A41: Green number (SKU tab) | B41: Inherits this tab's default — overtype to override one SKU
A42: Orange block (SKU tab) | B42: Current market prices you entered — benchmark only, not used in costing
A43: Red Σ% cell (SKU tab) | B43: % fish + % marinade ≠ 100% — fix the split
A44: Grey row (SKU tab) | B44: Status = Inactive
A47: =248946.7-63158 -> 185788.7
...

Sheet SKU Costing (Domestic)
A1: SKU Costing — DOMESTIC (LKR) · cost build-up only (pricing tiers removed for now)
A2: Main body = base cost WITHOUT glaze. Enter Glaze % (col D) per SKU; the two end blocks show FINAL without vs with glaze — no need to duplicate SKUs. | U2: WITHOUT GLAZE | W2: WITH GLAZE
A3: SKU | B3: Status | C3: Category | D3: Glaze % (unmarin.) | E3: Yield % | F3: % fish | G3: % mar- inade | H3: Σ % chk | I3: Whole fish LKR/kg | J3: Fish cost comp LKR | K3: Marinade $/kg | L3: Marinade comp LKR | M3: Raw matl LKR/kg | N3: Process $/kg | O3: Packing $/kg | P3: Cold-hold LKR/kg | Q3: Ex-factory LKR/kg | R3: Freight LKR/kg | S3: FINAL cost LKR/kg | T3: Pack size | U3: FINAL — no glaze LKR/kg | V3: RACK RATE — no glaze LKR/kg | W3: FINAL — glaze LKR/kg | X3: RACK RATE — glaze LKR/kg
A4: Whole round (ungutted) | B4: Active | C4: Whole | D4: 0 | E4: 0.98 | F4: 1 | G4: 0 | H4: =F4+G4 -> 1 | I4: ='Assumptions (Domestic)'!$B$21 -> 1099.375 | J4: =IFERROR(F4*I4/E4,0) -> 1121.8112 | K4: 0 | L4: =G4*K4*'Assumptions (Domestic)'!$B$20 -> 0 | M4: =J4+L4 -> 1121.8112 | N4: 0.4 | O4: 0.5 | P4: ='Assumptions (Domestic)'!$B$25 -> 40 | Q4: =M4+(N4+O4)*'Assumptions (Domestic)'!$B$20+P4 -> 1467.8112 | R4: ='Assumptions (Domestic)'!$B$24 -> 60 | S4: =Q4+R4 -> 1527.8112 | U4: =S4 -> 1527.8112 | V4: =IFERROR(U4/(1-'Assumptions (Domestic)'!$B$32),0) -> 2546.352 | W4: =S4-J4*D4/(1+D4) -> 1527.8112 | X4: =IFERROR(W4/(1-'Assumptions (Domestic)'!$B$32),0) -> 2546.352
A5: Whole gutted (WG) | B5: Active | C5: Whole | D5: 0 | E5: 0.92 | F5: 1 | G5: 0 | H5: =F5+G5 -> 1 | I5: ='Assumptions (Domestic)'!$B$21 -> 1099.375 | J5: =IFERROR(F5*I5/E5,0) -> 1194.9728 | K5: 0 | L5: =G5*K5*'Assumptions (Domestic)'!$B$20 -> 0 | M5: =J5+L5 -> 1194.9728 | N5: 0.45 | O5: 0.5 | P5: ='Assumptions (Domestic)'!$B$25 -> 40 | Q5: =M5+(N5+O5)*'Assumptions (Domestic)'!$B$20+P5 -> 1557.9728 | R5: ='Assumptions (Domestic)'!$B$24 -> 60 | S5: =Q5+R5 -> 1617.9728 | U5: =S5 -> 1617.9728 | V5: =IFERROR(U5/(1-'Assumptions (Domestic)'!$B$32),0) -> 2696.6214 | W5: =S5-J5*D5/(1+D5) -> 1617.9728 | X5: =IFERROR(W5/(1-'Assumptions (Domestic)'!$B$32),0) -> 2696.6214
A6: Whole gilled & gutted (WGG) | B6: Inactive | C6: Whole | D6: 0 | E6: 0.88 | F6: 1 | G6: 0 | H6: =F6+G6 -> 1 | I6: ='Assumptions (Domestic)'!$B$21 -> 1099.375 | J6: =IFERROR(F6*I6/E6,0) -> 1249.2898 | K6: 0 | L6: =G6*K6*'Assumptions (Domestic)'!$B$20 -> 0 | M6: =J6+L6 -> 1249.2898 | N6: 0.5 | O6: 0.5 | P6: ='Assumptions (Domestic)'!$B$25 -> 40 | Q6: =M6+(N6+O6)*'Assumptions (Domestic)'!$B$20+P6 -> 1629.2898 | R6: ='Assumptions (Domestic)'!$B$24 -> 60 | S6: =Q6+R6 -> 1689.2898 | U6: =S6 -> 1689.2898 | V6: =IFERROR(U6/(1-'Assumptions (Domestic)'!$B$32),0) -> 2815.483 | W6: =S6-J6*D6/(1+D6) -> 1689.2898 | X6: =IFERROR(W6/(1-'Assumptions (Domestic)'!$B$32),0) -> 2815.483
A7: Whole scaled & gutted | B7: Active | C7: Whole | D7: 0 | E7: 0.85 | F7: 1 | G7: 0 | H7: =F7+G7 -> 1 | I7: ='Assumptions (Domestic)'!$B$21 -> 1099.375 | J7: =IFERROR(F7*I7/E7,0) -> 1293.3824 | K7: 0 | L7: =G7*K7*'Assumptions (Domestic)'!$B$20 -> 0 | M7: =J7+L7 -> 1293.3824 | N7: 0.6 | O7: 0.5 | P7: ='Assumptions (Domestic)'!$B$25 -> 40 | Q7: =M7+(N7+O7)*'Assumptions (Domestic)'!$B$20+P7 -> 1707.3824 | R7: ='Assumptions (Domestic)'!$B$24 -> 60 | S7: =Q7+R7 -> 1767.3824 | U7: =S7 -> 1767.3824 | V7: =IFERROR(U7/(1-'Assumptions (Domestic)'!$B$32),0) -> 2945.6373 | W7: =S7-J7*D7/(1+D7) -> 1767.3824 | X7: =IFERROR(W7/(1-'Assumptions (Domestic)'!$B$32),0) -> 2945.6373
A8: Steaks / darne (bone-in) | B8: Active | C8: Whole | D8: 0 | E8: 0.82 | F8: 1 | G8: 0 | H8: =F8+G8 -> 1 | I8: ='Assumptions (Domestic)'!$B$21 -> 1099.375 | J8: =IFERROR(F8*I8/E8,0) -> 1340.7012 | K8: 0 | L8: =G8*K8*'Assumptions (Domestic)'!$B$20 -> 0 | M8: =J8+L8 -> 1340.7012 | N8: 0.45 | O8: 0.3 | P8: ='Assumptions (Domestic)'!$B$25 -> 40 | Q8: =M8+(N8+O8)*'Assumptions (Domestic)'!$B$20+P8 -> 1635.7012 | R8: ='Assumptions (Domestic)'!$B$24 -> 60 | S8: =Q8+R8 -> 1695.7012 | T8: 500g | U8: =S8 -> 1695.7012 | V8: =IFERROR(U8/(1-'Assumptions (Domestic)'!$B$32),0) -> 2826.1687 | W8: =S8-J8*D8/(1+D8) -> 1695.7012 | X8: =IFERROR(W8/(1-'Assumptions (Domestic)'!$B$32),0) -> 2826.1687
A9: Boat cut | B9: Inactive | C9: Whole | D9: 0 | E9: 0.75 | F9: 1 | G9: 0 | H9: =F9+G9 -> 1 | I9: ='Assumptions (Domestic)'!$B$21 -> 1099.375 | J9: =IFERROR(F9*I9/E9,0) -> 1465.8333 | K9: 0 | L9: =G9*K9*'Assumptions (Domestic)'!$B$20 -> 0 | M9: =J9+L9 -> 1465.8333 | N9: 0.55 | O9: 0.5 | P9: ='Assumptions (Domestic)'!$B$25 -> 40 | Q9: =M9+(N9+O9)*'Assumptions (Domestic)'!$B$20+P9 -> 1862.8333 | R9: ='Assumptions (Domestic)'!$B$24 -> 60 | S9: =Q9+R9 -> 1922.8333 | U9: =S9 -> 1922.8333 | V9: =IFERROR(U9/(1-'Assumptions (Domestic)'!$B$32),0) -> 3204.7222 | W9: =S9-J9*D9/(1+D9) -> 1922.8333 | X9: =IFERROR(W9/(1-'Assumptions (Domestic)'!$B$32),0) -> 3204.7222
A10: Butterfly cut | B10: Inactive | C10: Whole | D10: 0 | E10: 0.72 | F10: 1 | G10: 0 | H10: =F10+G10 -> 1 | I10: ='Assumptions (Domestic)'!$B$21 -> 1099.375 | J10: =IFERROR(F10*I10/E10,0) -> 1526.9097 | K10: 0 | L10: =G10*K10*'Assumptions (Domestic)'!$B$20 -> 0 | M10: =J10+L10 -> 1526.9097 | N10: 0.55 | O10: 0.5 | P10: ='Assumptions (Domestic)'!$B$25 -> 40 | Q10: =M10+(N10+O10)*'Assumptions (Domestic)'!$B$20+P10 -> 1923.9097 | R10: ='Assumptions (Domestic)'!$B$24 -> 60 | S10: =Q10+R10 -> 1983.9097 | U10: =S10 -> 1983.9097 | V10: =IFERROR(U10/(1-'Assumptions (Domestic)'!$B$32),0) -> 3306.5162 | W10: =S10-J10*D10/(1+D10) -> 1983.9097 | X10: =IFERROR(W10/(1-'Assumptions (Domestic)'!$B$32),0) -> 3306.5162
A11: Skin-on fillet | B11: Active | C11: Fillet | D11: 0 | E11: 0.45 | F11: 1 | G11: 0 | H11: =F11+G11 -> 1 | I11: ='Assumptions (Domestic)'!$B$21 -> 1099.375 | J11: =IFERROR(F11*I11/E11,0) -> 2443.0556 | K11: 0 | L11: =G11*K11*'Assumptions (Domestic)'!$B$20 -> 0 | M11: =J11+L11 -> 2443.0556 | N11: 1 | O11: 0.3 | P11: ='Assumptions (Domestic)'!$B$25 -> 40 | Q11: =M11+(N11+O11)*'Assumptions (Domestic)'!$B$20+P11 -> 2925.0556 | R11: ='Assumptions (Domestic)'!$B$24 -> 60 | S11: =Q11+R11 -> 2985.0556 | U11: =S11 -> 2985.0556 | V11: =IFERROR(U11/(1-'Assumptions (Domestic)'!$B$32),0) -> 4975.0926 | W11: =S11-J11*D11/(1+D11) -> 2985.0556 | X11: =IFERROR(W11/(1-'Assumptions (Domestic)'!$B$32),0) -> 4975.0926
A12: Skinless boneless fillet | B12: Active | C12: Fillet | D12: 0 | E12: 0.38 | F12: 1 | G12: 0 | H12: =F12+G12 -> 1 | I12: ='Assumptions (Domestic)'!$B$21 -> 1099.375 | J12: =IFERROR(F12*I12/E12,0) -> 2893.0921 | K12: 0 | L12: =G12*K12*'Assumptions (Domestic)'!$B$20 -> 0 | M12: =J12+L12 -> 2893.0921 | N12: 1 | O12: 0.3 | P12: ='Assumptions (Domestic)'!$B$25 -> 40 | Q12: =M12+(N12+O12)*'Assumptions (Domestic)'!$B$20+P12 -> 3375.0921 | R12: ='Assumptions (Domestic)'!$B$24 -> 60 | S12: =Q12+R12 -> 3435.0921 | U12: =S12 -> 3435.0921 | V12: =IFERROR(U12/(1-'Assumptions (Domestic)'!$B$32),0) -> 5725.1535 | W12: =S12-J12*D12/(1+D12) -> 3435.0921 | X12: =IFERROR(W12/(1-'Assumptions (Domestic)'!$B$32),0) -> 5725.1535
A13: Skinless fillet — premium trim | B13: Inactive | C13: Fillet | D13: 0 | E13: 0.34 | F13: 1 | G13: 0 | H13: =F13+G13 -> 1 | I13: ='Assumptions (Domestic)'!$B$21 -> 1099.375 | J13: =IFERROR(F13*I13/E13,0) -> 3233.4559 | K13: 0 | L13: =G13*K13*'Assumptions (Domestic)'!$B$20 -> 0 | M13: =J13+L13 -> 3233.4559 | N13: 1.25 | O13: 0.35 | P13: ='Assumptions (Domestic)'!$B$25 -> 40 | Q13: =M13+(N13+O13)*'Assumptions (Domestic)'!$B$20+P13 -> 3817.4559 | R13: ='Assumptions (Domestic)'!$B$24 -> 60 | S13: =Q13+R13 -> 3877.4559 | U13: =S13 -> 3877.4559 | V13: =IFERROR(U13/(1-'Assumptions (Domestic)'!$B$32),0) -> 6462.4265 | W13: =S13-J13*D13/(1+D13) -> 3877.4559 | X13: =IFERROR(W13/(1-'Assumptions (Domestic)'!$B$32),0) -> 6462.4265
A14: Fillet portions — skin-on CC | B14: Active | C14: Fillet | D14: 0 | E14: 0.32 | F14: 1 | G14: 0 | H14: =F14+G14 -> 1 | I14: ='Assumptions (Domestic)'!$B$21 -> 1099.375 | J14: =IFERROR(F14*I14/E14,0) -> 3435.5469 | K14: 0 | L14: =G14*K14*'Assumptions (Domestic)'!$B$20 -> 0 | M14: =J14+L14 -> 3435.5469 | N14: 1.15 | O14: 0.35 | P14: ='Assumptions (Domestic)'!$B$25 -> 40 | Q14: =M14+(N14+O14)*'Assumptions (Domestic)'!$B$20+P14 -> 3985.5469 | R14: ='Assumptions (Domestic)'!$B$24 -> 60 | S14: =Q14+R14 -> 4045.5469 | U14: =S14 -> 4045.5469 | V14: =IFERROR(U14/(1-'Assumptions (Domestic)'!$B$32),0) -> 6742.5781 | W14: =S14-J14*D14/(1+D14) -> 4045.5469 | X14: =IFERROR(W14/(1-'Assumptions (Domestic)'!$B$32),0) -> 6742.5781
A15: Fillet portions — skinless | B15: Inactive | C15: Fillet | D15: 0 | E15: 0.36 | F15: 1 | G15: 0 | H15: =F15+G15 -> 1 | I15: ='Assumptions (Domestic)'!$B$21 -> 1099.375 | J15: =IFERROR(F15*I15/E15,0) -> 3053.8194 | K15: 0 | L15: =G15*K15*'Assumptions (Domestic)'!$B$20 -> 0 | M15: =J15+L15 -> 3053.8194 | N15: 1.15 | O15: 0.35 | P15: ='Assumptions (Domestic)'!$B$25 -> 40 | Q15: =M15+(N15+O15)*'Assumptions (Domestic)'!$B$20+P15 -> 3603.8194 | R15: ='Assumptions (Domestic)'!$B$24 -> 60 | S15: =Q15+R15 -> 3663.8194 | U15: =S15 -> 3663.8194 | V15: =IFERROR(U15/(1-'Assumptions (Domestic)'!$B$32),0) -> 6106.3657 | W15: =S15-J15*D15/(1+D15) -> 3663.8194 | X15: =IFERROR(W15/(1-'Assumptions (Domestic)'!$B$32),0) -> 6106.3657
A16: Tail portions — regular (70/130) s/on | B16: Active | C16: Fillet | D16: 0 | E16: 0.3 | F16: 1 | G16: 0 | H16: =F16+G16 -> 1 | I16: ='Assumptions (Domestic)'!$B$21 -> 1099.375 | J16: =IFERROR(F16*I16/E16,0) -> 3664.5833 | K16: 0 | L16: =G16*K16*'Assumptions (Domestic)'!$B$20 -> 0 | M16: =J16+L16 -> 3664.5833 | N16: 1.15 | O16: 0.35 | P16: ='Assumptions (Domestic)'!$B$25 -> 40 | Q16: =M16+(N16+O16)*'Assumptions (Domestic)'!$B$20+P16 -> 4214.5833 | R16: ='Assumptions (Domestic)'!$B$24 -> 60 | S16: =Q16+R16 -> 4274.5833 | U16: =S16 -> 4274.5833 | V16: =IFERROR(U16/(1-'Assumptions (Domestic)'!$B$32),0) -> 7124.3056 | W16: =S16-J16*D16/(1+D16) -> 4274.5833 | X16: =IFERROR(W16/(1-'Assumptions (Domestic)'!$B$32),0) -> 7124.3056
A17: Tail portions — small (40/70) s/on | B17: Active | C17: Fillet | D17: 0 | E17: 0.28 | F17: 1 | G17: 0 | H17: =F17+G17 -> 1 | I17: ='Assumptions (Domestic)'!$B$21 -> 1099.375 | J17: =IFERROR(F17*I17/E17,0) -> 3926.3393 | K17: 0 | L17: =G17*K17*'Assumptions (Domestic)'!$B$20 -> 0 | M17: =J17+L17 -> 3926.3393 | N17: 1.2 | O17: 0.35 | P17: ='Assumptions (Domestic)'!$B$25 -> 40 | Q17: =M17+(N17+O17)*'Assumptions (Domestic)'!$B$20+P17 -> 4493.3393 | R17: ='Assumptions (Domestic)'!$B$24 -> 60 | S17: =Q17+R17 -> 4553.3393 | U17: =S17 -> 4553.3393 | V17: =IFERROR(U17/(1-'Assumptions (Domestic)'!$B$32),0) -> 7588.8988 | W17: =S17-J17*D17/(1+D17) -> 4553.3393 | X17: =IFERROR(W17/(1-'Assumptions (Domestic)'!$B$32),0) -> 7588.8988
A18: Fish cubes / stir-fry | B18: Active | C18: Fillet | D18: 0 | E18: 0.3 | F18: 1 | G18: 0 | H18: =F18+G18 -> 1 | I18: ='Assumptions (Domestic)'!$B$21 -> 1099.375 | J18: =IFERROR(F18*I18/E18,0) -> 3664.5833 | K18: 0 | L18: =G18*K18*'Assumptions (Domestic)'!$B$20 -> 0 | M18: =J18+L18 -> 3664.5833 | N18: 1.15 | O18: 0.33 | P18: ='Assumptions (Domestic)'!$B$25 -> 40 | Q18: =M18+(N18+O18)*'Assumptions (Domestic)'!$B$20+P18 -> 4207.7833 | R18: ='Assumptions (Domestic)'!$B$24 -> 60 | S18: =Q18+R18 -> 4267.7833 | T18: 500g | U18: =S18 -> 4267.7833 | V18: =IFERROR(U18/(1-'Assumptions (Domestic)'!$B$32),0) -> 7112.9722 | W18: =S18-J18*D18/(1+D18) -> 4267.7833 | X18: =IFERROR(W18/(1-'Assumptions (Domestic)'!$B$32),0) -> 7112.9722
A19: Loin portions | B19: Inactive | C19: Fillet | D19: 0 | E19: 0.3 | F19: 1 | G19: 0 | H19: =F19+G19 -> 1 | I19: ='Assumptions (Domestic)'!$B$21 -> 1099.375 | J19: =IFERROR(F19*I19/E19,0) -> 3664.5833 | K19: 0 | L19: =G19*K19*'Assumptions (Domestic)'!$B$20 -> 0 | M19: =J19+L19 -> 3664.5833 | N19: 1.15 | O19: 0.35 | P19: ='Assumptions (Domestic)'!$B$25 -> 40 | Q19: =M19+(N19+O19)*'Assumptions (Domestic)'!$B$20+P19 -> 4214.5833 | R19: ='Assumptions (Domestic)'!$B$24 -> 60 | S19: =Q19+R19 -> 4274.5833 | U19: =S19 -> 4274.5833 | V19: =IFERROR(U19/(1-'Assumptions (Domestic)'!$B$32),0) -> 7124.3056 | W19: =S19-J19*D19/(1+D19) -> 4274.5833 | X19: =IFERROR(W19/(1-'Assumptions (Domestic)'!$B$32),0) -> 7124.3056
A20: Belly flaps | B20: Active | C20: By-product | D20: 0 | E20: 0.06 | F20: 1 | G20: 0 | H20: =F20+G20 -> 1 | I20: ='Assumptions (Domestic)'!$B$21 -> 1099.375 | J20: =IFERROR(F20*I20/E20,0) -> 18322.917 | K20: 0 | L20: =G20*K20*'Assumptions (Domestic)'!$B$20 -> 0 | M20: =J20+L20 -> 18322.917 | N20: 0.2 | O20: 0.3 | P20: ='Assumptions (Domestic)'!$B$25 -> 40 | Q20: =M20+(N20+O20)*'Assumptions (Domestic)'!$B$20+P20 -> 18532.917 | R20: ='Assumptions (Domestic)'!$B$24 -> 60 | S20: =Q20+R20 -> 18592.917 | U20: =S20 -> 18592.917 | V20: =IFERROR(U20/(1-'Assumptions (Domestic)'!$B$32),0) -> 30988.194 | W20: =S20-J20*D20/(1+D20) -> 18592.917 | X20: =IFERROR(W20/(1-'Assumptions (Domestic)'!$B$32),0) -> 30988.194
A21: Head | B21: Inactive | C21: By-product | D21: 0 | E21: 0.11 | F21: 1 | G21: 0 | H21: =F21+G21 -> 1 | I21: ='Assumptions (Domestic)'!$B$21 -> 1099.375 | J21: =IFERROR(F21*I21/E21,0) -> 9994.3182 | K21: 0 | L21: =G21*K21*'Assumptions (Domestic)'!$B$20 -> 0 | M21: =J21+L21 -> 9994.3182 | N21: 0.2 | O21: 0.15 | P21: ='Assumptions (Domestic)'!$B$25 -> 40 | Q21: =M21+(N21+O21)*'Assumptions (Domestic)'!$B$20+P21 -> 10153.318 | R21: ='Assumptions (Domestic)'!$B$24 -> 60 | S21: =Q21+R21 -> 10213.318 | U21: =S21 -> 10213.318 | V21: =IFERROR(U21/(1-'Assumptions (Domestic)'!$B$32),0) -> 17022.197 | W21: =S21-J21*D21/(1+D21) -> 10213.318 | X21: =IFERROR(W21/(1-'Assumptions (Domestic)'!$B$32),0) -> 17022.197
A22: Collar | B22: Inactive | C22: By-product | D22: 0 | E22: 0.05 | F22: 1 | G22: 0 | H22: =F22+G22 -> 1 | I22: ='Assumptions (Domestic)'!$B$21 -> 1099.375 | J22: =IFERROR(F22*I22/E22,0) -> 21987.5 | K22: 0 | L22: =G22*K22*'Assumptions (Domestic)'!$B$20 -> 0 | M22: =J22+L22 -> 21987.5 | N22: 0.4 | O22: 0.25 | P22: ='Assumptions (Domestic)'!$B$25 -> 40 | Q22: =M22+(N22+O22)*'Assumptions (Domestic)'!$B$20+P22 -> 22248.5 | R22: ='Assumptions (Domestic)'!$B$24 -> 60 | S22: =Q22+R22 -> 22308.5 | U22: =S22 -> 22308.5 | V22: =IFERROR(U22/(1-'Assumptions (Domestic)'!$B$32),0) -> 37180.833 | W22: =S22-J22*D22/(1+D22) -> 22308.5 | X22: =IFERROR(W22/(1-'Assumptions (Domestic)'!$B$32),0) -> 37180.833
A23: Fish frames / bones (stock) | B23: Inactive | C23: By-product | D23: 0 | E23: 0.08 | F23: 1 | G23: 0 | H23: =F23+G23 -> 1 | I23: ='Assumptions (Domestic)'!$B$21 -> 1099.375 | J23: =IFERROR(F23*I23/E23,0) -> 13742.188 | K23: 0 | L23: =G23*K23*'Assumptions (Domestic)'!$B$20 -> 0 | M23: =J23+L23 -> 13742.188 | N23: 0.1 | O23: 0.15 | P23: ='Assumptions (Domestic)'!$B$25 -> 40 | Q23: =M23+(N23+O23)*'Assumptions (Domestic)'!$B$20+P23 -> 13867.188 | R23: ='Assumptions (Domestic)'!$B$24 -> 60 | S23: =Q23+R23 -> 13927.188 | U23: =S23 -> 13927.188 | V23: =IFERROR(U23/(1-'Assumptions (Domestic)'!$B$32),0) -> 23211.979 | W23: =S23-J23*D23/(1+D23) -> 13927.188 | X23: =IFERROR(W23/(1-'Assumptions (Domestic)'!$B$32),0) -> 23211.979
A24: Fish skin (crispy / pet treat) | B24: Inactive | C24: By-product | D24: 0 | E24: 0.03 | F24: 1 | G24: 0 | H24: =F24+G24 -> 1 | I24: ='Assumptions (Domestic)'!$B$21 -> 1099.375 | J24: =IFERROR(F24*I24/E24,0) -> 36645.833 | K24: 0 | L24: =G24*K24*'Assumptions (Domestic)'!$B$20 -> 0 | M24: =J24+L24 -> 36645.833 | N24: 0.2 | O24: 0.2 | P24: ='Assumptions (Domestic)'!$B$25 -> 40 | Q24: =M24+(N24+O24)*'Assumptions (Domestic)'!$B$20+P24 -> 36821.833 | R24: ='Assumptions (Domestic)'!$B$24 -> 60 | S24: =Q24+R24 -> 36881.833 | U24: =S24 -> 36881.833 | V24: =IFERROR(U24/(1-'Assumptions (Domestic)'!$B$32),0) -> 61469.722 | W24: =S24-J24*D24/(1+D24) -> 36881.833 | X24: =IFERROR(W24/(1-'Assumptions (Domestic)'!$B$32),0) -> 61469.722
A25: Trimmings / mince | B25: Inactive | C25: By-product | D25: 0 | E25: 0.07 | F25: 1 | G25: 0 | H25: =F25+G25 -> 1 | I25: ='Assumptions (Domestic)'!$B$21 -> 1099.375 | J25: =IFERROR(F25*I25/E25,0) -> 15705.357 | K25: 0 | L25: =G25*K25*'Assumptions (Domestic)'!$B$20 -> 0 | M25: =J25+L25 -> 15705.357 | N25: 0.2 | O25: 0.2 | P25: ='Assumptions (Domestic)'!$B$25 -> 40 | Q25: =M25+(N25+O25)*'Assumptions (Domestic)'!$B$20+P25 -> 15881.357 | R25: ='Assumptions (Domestic)'!$B$24 -> 60 | S25: =Q25+R25 -> 15941.357 | U25: =S25 -> 15941.357 | V25: =IFERROR(U25/(1-'Assumptions (Domestic)'!$B$32),0) -> 26568.929 | W25: =S25-J25*D25/(1+D25) -> 15941.357 | X25: =IFERROR(W25/(1-'Assumptions (Domestic)'!$B$32),0) -> 26568.929
A26: Marinated fillet — lemon herb | B26: Inactive | C26: Value-added | D26: 0 | E26: 0.38 | F26: 0.82 | G26: 0.18 | H26: =F26+G26 -> 1 | I26: ='Assumptions (Domestic)'!$B$21 -> 1099.375 | J26: =IFERROR(F26*I26/E26,0) -> 2372.3355 | K26: 1.8 | L26: =G26*K26*'Assumptions (Domestic)'!$B$20 -> 110.16 | M26: =J26+L26 -> 2482.4955 | N26: 1.4 | O26: 0.45 | P26: ='Assumptions (Domestic)'!$B$25 -> 40 | Q26: =M26+(N26+O26)*'Assumptions (Domestic)'!$B$20+P26 -> 3151.4955 | R26: ='Assumptions (Domestic)'!$B$24 -> 60 | S26: =Q26+R26 -> 3211.4955 | U26: =S26 -> 3211.4955 | V26: =IFERROR(U26/(1-'Assumptions (Domestic)'!$B$32),0) -> 5352.4925 | W26: =S26-J26*D26/(1+D26) -> 3211.4955 | X26: =IFERROR(W26/(1-'Assumptions (Domestic)'!$B$32),0) -> 5352.4925
A27: Marinated fillet — hot & spicy | B27: Inactive | C27: Value-added | D27: 0 | E27: 0.38 | F27: 0.82 | G27: 0.18 | H27: =F27+G27 -> 1 | I27: ='Assumptions (Domestic)'!$B$21 -> 1099.375 | J27: =IFERROR(F27*I27/E27,0) -> 2372.3355 | K27: 1.6 | L27: =G27*K27*'Assumptions (Domestic)'!$B$20 -> 97.92 | M27: =J27+L27 -> 2470.2555 | N27: 1.4 | O27: 0.45 | P27: ='Assumptions (Domestic)'!$B$25 -> 40 | Q27: =M27+(N27+O27)*'Assumptions (Domestic)'!$B$20+P27 -> 3139.2555 | R27: ='Assumptions (Domestic)'!$B$24 -> 60 | S27: =Q27+R27 -> 3199.2555 | U27: =S27 -> 3199.2555 | V27: =IFERROR(U27/(1-'Assumptions (Domestic)'!$B$32),0) -> 5332.0925 | W27: =S27-J27*D27/(1+D27) -> 3199.2555 | X27: =IFERROR(W27/(1-'Assumptions (Domestic)'!$B$32),0) -> 5332.0925
A28: Marinated portions — BBQ | B28: Inactive | C28: Value-added | D28: 0 | E28: 0.36 | F28: 0.8 | G28: 0.2 | H28: =F28+G28 -> 1 | I28: ='Assumptions (Domestic)'!$B$21 -> 1099.375 | J28: =IFERROR(F28*I28/E28,0) -> 2443.0556 | K28: 1.7 | L28: =G28*K28*'Assumptions (Domestic)'!$B$20 -> 115.6 | M28: =J28+L28 -> 2558.6556 | N28: 1.3 | O28: 0.45 | P28: ='Assumptions (Domestic)'!$B$25 -> 40 | Q28: =M28+(N28+O28)*'Assumptions (Domestic)'!$B$20+P28 -> 3193.6556 | R28: ='Assumptions (Domestic)'!$B$24 -> 60 | S28: =Q28+R28 -> 3253.6556 | U28: =S28 -> 3253.6556 | V28: =IFERROR(U28/(1-'Assumptions (Domestic)'!$B$32),0) -> 5422.7593 | W28: =S28-J28*D28/(1+D28) -> 3253.6556 | X28: =IFERROR(W28/(1-'Assumptions (Domestic)'!$B$32),0) -> 5422.7593
A29: Marinated cubes — curry cut | B29: Inactive | C29: Value-added | D29: 0 | E29: 0.35 | F29: 0.78 | G29: 0.22 | H29: =F29+G29 -> 1 | I29: ='Assumptions (Domestic)'!$B$21 -> 1099.375 | J29: =IFERROR(F29*I29/E29,0) -> 2450.0357 | K29: 1.5 | L29: =G29*K29*'Assumptions (Domestic)'!$B$20 -> 112.2 | M29: =J29+L29 -> 2562.2357 | N29: 1.35 | O29: 0.45 | P29: ='Assumptions (Domestic)'!$B$25 -> 40 | Q29: =M29+(N29+O29)*'Assumptions (Domestic)'!$B$20+P29 -> 3214.2357 | R29: ='Assumptions (Domestic)'!$B$24 -> 60 | S29: =Q29+R29 -> 3274.2357 | U29: =S29 -> 3274.2357 | V29: =IFERROR(U29/(1-'Assumptions (Domestic)'!$B$32),0) -> 5457.0595 | W29: =S29-J29*D29/(1+D29) -> 3274.2357 | X29: =IFERROR(W29/(1-'Assumptions (Domestic)'!$B$32),0) -> 5457.0595
A30: Teriyaki glazed portions | B30: Inactive | C30: Value-added | D30: 0 | E30: 0.36 | F30: 0.78 | G30: 0.22 | H30: =F30+G30 -> 1 | I30: ='Assumptions (Domestic)'!$B$21 -> 1099.375 | J30: =IFERROR(F30*I30/E30,0) -> 2381.9792 | K30: 2.2 | L30: =G30*K30*'Assumptions (Domestic)'!$B$20 -> 164.56 | M30: =J30+L30 -> 2546.5392 | N30: 1.45 | O30: 0.5 | P30: ='Assumptions (Domestic)'!$B$25 -> 40 | Q30: =M30+(N30+O30)*'Assumptions (Domestic)'!$B$20+P30 -> 3249.5392 | R30: ='Assumptions (Domestic)'!$B$24 -> 60 | S30: =Q30+R30 -> 3309.5392 | U30: =S30 -> 3309.5392 | V30: =IFERROR(U30/(1-'Assumptions (Domestic)'!$B$32),0) -> 5515.8986 | W30: =S30-J30*D30/(1+D30) -> 3309.5392 | X30: =IFERROR(W30/(1-'Assumptions (Domestic)'!$B$32),0) -> 5515.8986
... A37: Smoked fillet | B37: Inactive | C37: Value-added | D37: 0 | E37: 0.38 | F37: 0.95 | G37: 0.05 | H37: =F37+G37 -> 1 | I37: ='Assumptions (Domestic)'!$B$21 -> 1099.375 | J37: =IFERROR(F37*I37/E37,0) -> 2748.4375 | K37: 1.5 | L37: =G37*K37*'Assumptions (Domestic)'!$B$20 -> 25.5 | M37: =J37+L37 -> 2773.9375 | N37: 2.2 | O37: 0.6 | P37: ='Assumptions (Domestic)'!$B$25 -> 40 | Q37: =M37+(N37+O37)*'Assumptions (Domestic)'!$B$20+P37 -> 3765.9375 | R37: ='Assumptions (Domestic)'!$B$24 -> 60 | S37: =Q37+R37 -> 3825.9375 | U37: =S37 -> 3825.9375 | V37: =IFERROR(U37/(1-'Assumptions (Domestic)'!$B$32),0) -> 6376.5625 | W37: =S37-J37*D37/(1+D37) -> 3825.9375 | X37: =IFERROR(W37/(1-'Assumptions (Domestic)'!$B$32),0) -> 6376.5625

Sheet Assumptions (Export)
A1: Barramundi Costing & Pricing — EXPORT (USD)
A2: Farm costs (feed, clearing, FCR, ODC) are INHERITED from the Domestic tab — no re-entry. Edit only yellow cells here: import tax (0), export adders, margins & the value chain.
A4: 1. BASE FISH COST — USD (farm costs inherited from Domestic; only tax differs)
A5: Feed cost/kg | B5: ='Assumptions (Domestic)'!$B$5 -> 1.35 | C5: ◄ from Domestic (edit there)
A6: Clearing cost/kg | B6: ='Assumptions (Domestic)'!$B$6 -> 0.05 | C6: ◄ from Domestic
A7: Import tax on feed | B7: 0 | C7: EXPORT: nil — duty drawback ◄ the ONLY base difference
A8: Effective feed cost | B8: =B5*(1+B7)+B6 -> 1.4 | C8: USD/kg feed incl. tax + clearing
A9: FCR (feed conversion ratio) | B9: ='Assumptions (Domestic)'!$B$9 -> 1.5 | C9: ◄ from Domestic
A10: Feed cost per kg of fish | B10: =B8*B9 -> 2.1 | C10: USD/kg live fish
A11: ODC — other direct costs | B11: ='Assumptions (Domestic)'!$B$11 -> 0.42470588 | C11: ◄ from Domestic (full breakdown there)
A12: Whole fish cost | B12: =B10+B11 -> 2.5247059 | C12: USD/kg ◄ feeds Export SKU tab
A13: FX rate (reference only) | B13: 340 | C13: LKR per 1 USD — NOT used in export pricing
A14: Whole fish cost (LKR ref.) | B14: =B12*B13 -> 858.4 | C14: LKR/kg — reference cross-check only
A16: 2. COMMON PER-KG ADDERS (USD/kg) — export-specific
A17: Freight to port | B17: 0.1 | C17: USD/kg — factory→port (our cost, into FINAL)
A18: Cold-chain / holding | B18: 0.1 | C18: USD/kg — reefer / cold storage
A20: 3. (legacy margin tiers removed — the FOB value-chain below is primary)
A25: 4. EXPORT VALUE CHAIN (FOB → importer → distributor → T3)
A26: FOB — our margin (GM%) | B26: 0.4 | C26: our gross margin on FINAL → FOB / rack rate
A27: Destination freight (legacy — superseded ▼) | B27: 0.5 | C27: now driven by the Destinations table below
A28: Importer clearing % | B28: 0.05 | C28: importer's clearing cost on CNF
A29: Importer markup % | B29: 0.1 | C29: importer's markup to distributor
A30: Distributor markup % | B30: 0.15 | C30: distributor's markup to T3 (restaurants/foodservice)
A32: Green cells are inherited from Domestic — edit them on the Domestic tab. To make an export cost genuinely differ, overtype the green cell (it breaks that link only).
A34: 5. DESTINATIONS — enter 20ft-container & air-lot rates; per-kg auto-computed; CIF varies by port
A35: Selected destination ► | B35: Dubai (UAE) | C35: ◄ pick a port; CIF below recomputes for it
A36: Sea freight (selected) | B36: =IFERROR(VLOOKUP($B$35,$A$42:$E$62,4,FALSE()),0) -> 0.45 | C36: USD/kg — frozen (sea)
A37: Air freight (selected) | B37: =IFERROR(VLOOKUP($B$35,$A$42:$E$62,5,FALSE()),0) -> 2.8 | C37: USD/kg — fresh (air)
A38: Container fill weight (kg) | B38: 7000 | C38: kg of product that fills one 20ft reefer (editable)
A39: Air lot weight (kg) | B39: 500 | C39: kg per air consignment (editable)
A41: Destination | B41: Sea $ / 20ft | C41: Air $ / lot | D41: → Sea $/kg | E41: → Air $/kg
A42: Dubai (UAE) | B42: 3150 | C42: 1400 | D42: =IFERROR(B42/$B$38,0) -> 0.45 | E42: =IFERROR(C42/$B$39,0) -> 2.8
A43: Singapore | B43: 2800 | C43: 1250 | D43: =IFERROR(B43/$B$38,0) -> 0.4 | E43: =IFERROR(C43/$B$39,0) -> 2.5
A44: Doha (Qatar) | B44: 3500 | C44: 1450 | D44: =IFERROR(B44/$B$38,0) -> 0.5 | E44: =IFERROR(C44/$B$39,0) -> 2.9
A45: Male (Maldives) | B45: 2450 | C45: 900 | D45: =IFERROR(B45/$B$38,0) -> 0.35 | E45: =IFERROR(C45/$B$39,0) -> 1.8
A46: Hong Kong | B46: 3150 | C46: 1300 | D46: =IFERROR(B46/$B$38,0) -> 0.45 | E46: =IFERROR(C46/$B$39,0) -> 2.6
A47: London (UK) | B47: 5950 | C47: 2250 | D47: =IFERROR(B47/$B$38,0) -> 0.85 | E47: =IFERROR(C47/$B$39,0) -> 4.5
A48: Sydney (AU) | B48: 4900 | C48: 1900 | D48: =IFERROR(B48/$B$38,0) -> 0.7 | E48: =IFERROR(C48/$B$39,0) -> 3.8
A49: New York (US) | B49: 7700 | C49: 2750 | D49: =IFERROR(B49/$B$38,0) -> 1.1 | E49: =IFERROR(C49/$B$39,0) -> 5.5
A50: Melbourne (AU) | B50: 5200 | C50: 2000 | D50: =IFERROR(B50/$B$38,0) -> 0.74285714 | E50: =IFERROR(C50/$B$39,0) -> 4
...

Sheet SKU Costing (Export)
A1: SKU Costing — EXPORT (USD) · cost build-up + FOB → CNF → Importer → Distributor→T3
A2: Main body = base cost WITHOUT glaze. Glaze % (col D) drives the WITH-GLAZE block (FINAL/FOB/Dist→T3). No duplicate SKUs needed. | U2: FROZEN · NO GLAZE (sea) | Y2: FROZEN · GLAZE (sea) | AC2: FRESH (air)
A3: SKU | B3: Status | C3: Category | D3: Glaze % (unmarin.) | E3: Yield % | F3: % fish | G3: % mar- inade | H3: Σ % chk | I3: Whole fish $/kg | J3: Fish cost comp $ | K3: Marinade $/kg | L3: Marinade comp $ | M3: Raw matl $/kg | N3: Process $/kg | O3: Packing $/kg | P3: Cold-hold $/kg | Q3: Ex-factory $/kg | R3: Freight $/kg | S3: FINAL cost $/kg | T3: Pack size | U3: FINAL $/kg | V3: FOB $/kg | W3: CIF $/kg | X3: Dist→T3 $/kg | Y3: FINAL $/kg | Z3: FOB $/kg | AA3: CIF $/kg | AB3: Dist→T3 $/kg | AC3: FINAL $/kg | AD3: FOB $/kg | AE3: CIF $/kg | AF3: Dist→T3 $/kg
A4: Whole round (ungutted) | B4: Active | C4: Whole | D4: 0 | E4: 0.98 | F4: 1 | G4: 0 | H4: =F4+G4 -> 1 | I4: ='Assumptions (Export)'!$B$12 -> 2.5247059 | J4: =IFERROR(F4*I4/E4,0) -> 2.5762305 | K4: 0 | L4: =G4*K4 -> 0 | M4: =J4+L4 -> 2.5762305 | N4: 0.4 | O4: 0.5 | P4: ='Assumptions (Export)'!$B$18 -> 0.1 | Q4: =M4+N4+O4+P4 -> 3.5762305 | R4: ='Assumptions (Export)'!$B$17 -> 0.1 | S4: =Q4+R4 -> 3.6762305 | U4: =S4 -> 3.6762305 | V4: =IFERROR(S4/(1-'Assumptions (Export)'!$B$26),0) -> 6.1270508 | W4: =V4+'Assumptions (Export)'!$B$36 -> 6.5770508 | X4: =W4*(1+'Assumptions (Export)'!$B$28)*(1+'Assumptions (Export)'!$B$29)*(1+'Assumptions (Export)'!$B$30) -> 8.7359678 | Y4: =S4-J4*D4/(1+D4) -> 3.6762305 | Z4: =IFERROR(Y4/(1-'Assumptions (Export)'!$B$26),0) -> 6.1270508 | AA4: =Z4+'Assumptions (Export)'!$B$36 -> 6.5770508 | AB4: =AA4*(1+'Assumptions (Export)'!$B$28)*(1+'Assumptions (Export)'!$B$29)*(1+'Assumptions (Export)'!$B$30) -> 8.7359678 | AC4: =S4 -> 3.6762305 | AD4: =IFERROR(S4/(1-'Assumptions (Export)'!$B$26),0) -> 6.1270508 | AE4: =AD4+'Assumptions (Export)'!$B$37 -> 8.9270508 | AF4: =AE4*(1+'Assumptions (Export)'!$B$28)*(1+'Assumptions (Export)'!$B$29)*(1+'Assumptions (Export)'!$B$30) -> 11.857355
A5: Whole gutted (WG) | B5: Active | C5: Whole | D5: 0 | E5: 0.92 | F5: 1 | G5: 0 | H5: =F5+G5 -> 1 | I5: ='Assumptions (Export)'!$B$12 -> 2.5247059 | J5: =IFERROR(F5*I5/E5,0) -> 2.7442455 | K5: 0 | L5: =G5*K5 -> 0 | M5: =J5+L5 -> 2.7442455 | N5: 0.45 | O5: 0.5 | P5: ='Assumptions (Export)'!$B$18 -> 0.1 | Q5: =M5+N5+O5+P5 -> 3.7942455 | R5: ='Assumptions (Export)'!$B$17 -> 0.1 | S5: =Q5+R5 -> 3.8942455 | U5: =S5 -> 3.8942455 | V5: =IFERROR(S5/(1-'Assumptions (Export)'!$B$26),0) -> 6.4904092 | W5: =V5+'Assumptions (Export)'!$B$36 -> 6.9404092 | X5: =W5*(1+'Assumptions (Export)'!$B$28)*(1+'Assumptions (Export)'!$B$29)*(1+'Assumptions (Export)'!$B$30) -> 9.2185985 | Y5: =S5-J5*D5/(1+D5) -> 3.8942455 | Z5: =IFERROR(Y5/(1-'Assumptions (Export)'!$B$26),0) -> 6.4904092 | AA5: =Z5+'Assumptions (Export)'!$B$36 -> 6.9404092 | AB5: =AA5*(1+'Assumptions (Export)'!$B$28)*(1+'Assumptions (Export)'!$B$29)*(1+'Assumptions (Export)'!$B$30) -> 9.2185985 | AC5: =S5 -> 3.8942455 | AD5: =IFERROR(S5/(1-'Assumptions (Export)'!$B$26),0) -> 6.4904092 | AE5: =AD5+'Assumptions (Export)'!$B$37 -> 9.2904092 | AF5: =AE5*(1+'Assumptions (Export)'!$B$28)*(1+'Assumptions (Export)'!$B$29)*(1+'Assumptions (Export)'!$B$30) -> 12.339986
A6: Whole gilled & gutted (WGG) | B6: Inactive | C6: Whole | D6: 0 | E6: 0.88 | F6: 1 | G6: 0 | H6: =F6+G6 -> 1 | I6: ='Assumptions (Export)'!$B$12 -> 2.5247059 | J6: =IFERROR(F6*I6/E6,0) -> 2.868984 | K6: 0 | L6: =G6*K6 -> 0 | M6: =J6+L6 -> 2.868984 | N6: 0.5 | O6: 0.5 | P6: ='Assumptions (Export)'!$B$18 -> 0.1 | Q6: =M6+N6+O6+P6 -> 3.968984 | R6: ='Assumptions (Export)'!$B$17 -> 0.1 | S6: =Q6+R6 -> 4.068984 | U6: =S6 -> 4.068984 | V6: =IFERROR(S6/(1-'Assumptions (Export)'!$B$26),0) -> 6.7816399 | W6: =V6+'Assumptions (Export)'!$B$36 -> 7.2316399 | X6: =W6*(1+'Assumptions (Export)'!$B$28)*(1+'Assumptions (Export)'!$B$29)*(1+'Assumptions (Export)'!$B$30) -> 9.6054257 | Y6: =S6-J6*D6/(1+D6) -> 4.068984 | Z6: =IFERROR(Y6/(1-'Assumptions (Export)'!$B$26),0) -> 6.7816399 | AA6: =Z6+'Assumptions (Export)'!$B$36 -> 7.2316399 | AB6: =AA6*(1+'Assumptions (Export)'!$B$28)*(1+'Assumptions (Export)'!$B$29)*(1+'Assumptions (Export)'!$B$30) -> 9.6054257 | AC6: =S6 -> 4.068984 | AD6: =IFERROR(S6/(1-'Assumptions (Export)'!$B$26),0) -> 6.7816399 | AE6: =AD6+'Assumptions (Export)'!$B$37 -> 9.5816399 | AF6: =AE6*(1+'Assumptions (Export)'!$B$28)*(1+'Assumptions (Export)'!$B$29)*(1+'Assumptions (Export)'!$B$30) -> 12.726813
A7: Whole scaled & gutted | B7: Active | C7: Whole | D7: 0 | E7: 0.85 | F7: 1 | G7: 0 | H7: =F7+G7 -> 1 | I7: ='Assumptions (Export)'!$B$12 -> 2.5247059 | J7: =IFERROR(F7*I7/E7,0) -> 2.9702422 | K7: 0 | L7: =G7*K7 -> 0 | M7: =J7+L7 -> 2.9702422 | N7: 0.6 | O7: 0.5 | P7: ='Assumptions (Export)'!$B$18 -> 0.1 | Q7: =M7+N7+O7+P7 -> 4.1702422 | R7: ='Assumptions (Export)'!$B$17 -> 0.1 | S7: =Q7+R7 -> 4.2702422 | U7: =S7 -> 4.2702422 | V7: =IFERROR(S7/(1-'Assumptions (Export)'!$B$26),0) -> 7.1170704 | W7: =V7+'Assumptions (Export)'!$B$36 -> 7.5670704 | X7: =W7*(1+'Assumptions (Export)'!$B$28)*(1+'Assumptions (Export)'!$B$29)*(1+'Assumptions (Export)'!$B$30) -> 10.050961 | Y7: =S7-J7*D7/(1+D7) -> 4.2702422 | Z7: =IFERROR(Y7/(1-'Assumptions (Export)'!$B$26),0) -> 7.1170704 | AA7: =Z7+'Assumptions (Export)'!$B$36 -> 7.5670704 | AB7: =AA7*(1+'Assumptions (Export)'!$B$28)*(1+'Assumptions (Export)'!$B$29)*(1+'Assumptions (Export)'!$B$30) -> 10.050961 | AC7: =S7 -> 4.2702422 | AD7: =IFERROR(S7/(1-'Assumptions (Export)'!$B$26),0) -> 7.1170704 | AE7: =AD7+'Assumptions (Export)'!$B$37 -> 9.9170704 | AF7: =AE7*(1+'Assumptions (Export)'!$B$28)*(1+'Assumptions (Export)'!$B$29)*(1+'Assumptions (Export)'!$B$30) -> 13.172349
A8: Steaks / darne (bone-in) | B8: Active | C8: Whole | D8: 0 | E8: 0.82 | F8: 1 | G8: 0 | H8: =F8+G8 -> 1 | I8: ='Assumptions (Export)'!$B$12 -> 2.5247059 | J8: =IFERROR(F8*I8/E8,0) -> 3.0789096 | K8: 0 | L8: =G8*K8 -> 0 | M8: =J8+L8 -> 3.0789096 | N8: 0.45 | O8: 0.3 | P8: ='Assumptions (Export)'!$B$18 -> 0.1 | Q8: =M8+N8+O8+P8 -> 3.9289096 | R8: ='Assumptions (Export)'!$B$17 -> 0.1 | S8: =Q8+R8 -> 4.0289096 | U8: =S8 -> 4.0289096 | V8: =IFERROR(S8/(1-'Assumptions (Export)'!$B$26),0) -> 6.7148494 | W8: =V8+'Assumptions (Export)'!$B$36 -> 7.1648494 | X8: =W8*(1+'Assumptions (Export)'!$B$28)*(1+'Assumptions (Export)'!$B$29)*(1+'Assumptions (Export)'!$B$30) -> 9.5167112 | Y8: =S8-J8*D8/(1+D8) -> 4.0289096 | Z8: =IFERROR(Y8/(1-'Assumptions (Export)'!$B$26),0) -> 6.7148494 | AA8: =Z8+'Assumptions (Export)'!$B$36 -> 7.1648494 | AB8: =AA8*(1+'Assumptions (Export)'!$B$28)*(1+'Assumptions (Export)'!$B$29)*(1+'Assumptions (Export)'!$B$30) -> 9.5167112 | AC8: =S8 -> 4.0289096 | AD8: =IFERROR(S8/(1-'Assumptions (Export)'!$B$26),0) -> 6.7148494 | AE8: =AD8+'Assumptions (Export)'!$B$37 -> 9.5148494 | AF8: =AE8*(1+'Assumptions (Export)'!$B$28)*(1+'Assumptions (Export)'!$B$29)*(1+'Assumptions (Export)'!$B$30) -> 12.638099
A9: Boat cut | B9: Inactive | C9: Whole | D9: 0 | E9: 0.75 | F9: 1 | G9: 0 | H9: =F9+G9 -> 1 | I9: ='Assumptions (Export)'!$B$12 -> 2.5247059 | J9: =IFERROR(F9*I9/E9,0) -> 3.3662745 | K9: 0 | L9: =G9*K9 -> 0 | M9: =J9+L9 -> 3.3662745 | N9: 0.55 | O9: 0.5 | P9: ='Assumptions (Export)'!$B$18 -> 0.1 | Q9: =M9+N9+O9+P9 -> 4.5162745 | R9: ='Assumptions (Export)'!$B$17 -> 0.1 | S9: =Q9+R9 -> 4.6162745 | U9: =S9 -> 4.6162745 | V9: =IFERROR(S9/(1-'Assumptions (Export)'!$B$26),0) -> 7.6937908 | W9: =V9+'Assumptions (Export)'!$B$36 -> 8.1437908 | X9: =W9*(1+'Assumptions (Export)'!$B$28)*(1+'Assumptions (Export)'!$B$29)*(1+'Assumptions (Export)'!$B$30) -> 10.81699 | Y9: =S9-J9*D9/(1+D9) -> 4.6162745 | Z9: =IFERROR(Y9/(1-'Assumptions (Export)'!$B$26),0) -> 7.6937908 | AA9: =Z9+'Assumptions (Export)'!$B$36 -> 8.1437908 | AB9: =AA9*(1+'Assumptions (Export)'!$B$28)*(1+'Assumptions (Export)'!$B$29)*(1+'Assumptions (Export)'!$B$30) -> 10.81699 | AC9: =S9 -> 4.6162745 | AD9: =IFERROR(S9/(1-'Assumptions (Export)'!$B$26),0) -> 7.6937908 | AE9: =AD9+'Assumptions (Export)'!$B$37 -> 10.493791 | AF9: =AE9*(1+'Assumptions (Export)'!$B$28)*(1+'Assumptions (Export)'!$B$29)*(1+'Assumptions (Export)'!$B$30) -> 13.938378
A10: Butterfly cut | B10: Inactive | C10: Whole | D10: 0 | E10: 0.72 | F10: 1 | G10: 0 | H10: =F10+G10 -> 1 | I10: ='Assumptions (Export)'!$B$12 -> 2.5247059 | J10: =IFERROR(F10*I10/E10,0) -> 3.5065359 | K10: 0 | L10: =G10*K10 -> 0 | M10: =J10+L10 -> 3.5065359 | N10: 0.55 | O10: 0.5 | P10: ='Assumptions (Export)'!$B$18 -> 0.1 | Q10: =M10+N10+O10+P10 -> 4.6565359 | R10: ='Assumptions (Export)'!$B$17 -> 0.1 | S10: =Q10+R10 -> 4.7565359 | U10: =S10 -> 4.7565359 | V10: =IFERROR(S10/(1-'Assumptions (Export)'!$B$26),0) -> 7.9275599 | W10: =V10+'Assumptions (Export)'!$B$36 -> 8.3775599 | X10: =W10*(1+'Assumptions (Export)'!$B$28)*(1+'Assumptions (Export)'!$B$29)*(1+'Assumptions (Export)'!$B$30) -> 11.127494 | Y10: =S10-J10*D10/(1+D10) -> 4.7565359 | Z10: =IFERROR(Y10/(1-'Assumptions (Export)'!$B$26),0) -> 7.9275599 | AA10: =Z10+'Assumptions (Export)'!$B$36 -> 8.3775599 | AB10: =AA10*(1+'Assumptions (Export)'!$B$28)*(1+'Assumptions (Export)'!$B$29)*(1+'Assumptions (Export)'!$B$30) -> 11.127494 | AC10: =S10 -> 4.7565359 | AD10: =IFERROR(S10/(1-'Assumptions (Export)'!$B$26),0) -> 7.9275599 | AE10: =AD10+'Assumptions (Export)'!$B$37 -> 10.72756 | AF10: =AE10*(1+'Assumptions (Export)'!$B$28)*(1+'Assumptions (Export)'!$B$29)*(1+'Assumptions (Export)'!$B$30) -> 14.248881
A11: Skin-on fillet | B11: Active | C11: Fillet | D11: 0 | E11: 0.45 | F11: 1 | G11: 0 | H11: =F11+G11 -> 1 | I11: ='Assumptions (Export)'!$B$12 -> 2.5247059 | J11: =IFERROR(F11*I11/E11,0) -> 5.6104575 | K11: 0 | L11: =G11*K11 -> 0 | M11: =J11+L11 -> 5.6104575 | N11: 1 | O11: 0.3 | P11: ='Assumptions (Export)'!$B$18 -> 0.1 | Q11: =M11+N11+O11+P11 -> 7.0104575 | R11: ='Assumptions (Export)'!$B$17 -> 0.1 | S11: =Q11+R11 -> 7.1104575 | U11: =S11 -> 7.1104575 | V11: =IFERROR(S11/(1-'Assumptions (Export)'!$B$26),0) -> 11.850763 | W11: =V11+'Assumptions (Export)'!$B$36 -> 12.300763 | X11: =W11*(1+'Assumptions (Export)'!$B$28)*(1+'Assumptions (Export)'!$B$29)*(1+'Assumptions (Export)'!$B$30) -> 16.338488 | Y11: =S11-J11*D11/(1+D11) -> 7.1104575 | Z11: =IFERROR(Y11/(1-'Assumptions (Export)'!$B$26),0) -> 11.850763 | AA11: =Z11+'Assumptions (Export)'!$B$36 -> 12.300763 | AB11: =AA11*(1+'Assumptions (Export)'!$B$28)*(1+'Assumptions (Export)'!$B$29)*(1+'Assumptions (Export)'!$B$30) -> 16.338488 | AC11: =S11 -> 7.1104575 | AD11: =IFERROR(S11/(1-'Assumptions (Export)'!$B$26),0) -> 11.850763 | AE11: =AD11+'Assumptions (Export)'!$B$37 -> 14.650763 | AF11: =AE11*(1+'Assumptions (Export)'!$B$28)*(1+'Assumptions (Export)'!$B$29)*(1+'Assumptions (Export)'!$B$30) -> 19.459875
A12: Skinless boneless fillet | B12: Active | C12: Fillet | D12: 0 | E12: 0.38 | F12: 1 | G12: 0 | H12: =F12+G12 -> 1 | I12: ='Assumptions (Export)'!$B$12 -> 2.5247059 | J12: =IFERROR(F12*I12/E12,0) -> 6.6439628 | K12: 0 | L12: =G12*K12 -> 0 | M12: =J12+L12 -> 6.6439628 | N12: 1 | O12: 0.3 | P12: ='Assumptions (Export)'!$B$18 -> 0.1 | Q12: =M12+N12+O12+P12 -> 8.0439628 | R12: ='Assumptions (Export)'!$B$17 -> 0.1 | S12: =Q12+R12 -> 8.1439628 | U12: =S12 -> 8.1439628 | V12: =IFERROR(S12/(1-'Assumptions (Export)'!$B$26),0) -> 13.573271 | W12: =V12+'Assumptions (Export)'!$B$36 -> 14.023271 | X12: =W12*(1+'Assumptions (Export)'!$B$28)*(1+'Assumptions (Export)'!$B$29)*(1+'Assumptions (Export)'!$B$30) -> 18.62641 | Y12: =S12-J12*D12/(1+D12) -> 8.1439628 | Z12: =IFERROR(Y12/(1-'Assumptions (Export)'!$B$26),0) -> 13.573271 | AA12: =Z12+'Assumptions (Export)'!$B$36 -> 14.023271 | AB12: =AA12*(1+'Assumptions (Export)'!$B$28)*(1+'Assumptions (Export)'!$B$29)*(1+'Assumptions (Export)'!$B$30) -> 18.62641 | AC12: =S12 -> 8.1439628 | AD12: =IFERROR(S12/(1-'Assumptions (Export)'!$B$26),0) -> 13.573271 | AE12: =AD12+'Assumptions (Export)'!$B$37 -> 16.373271 | AF12: =AE12*(1+'Assumptions (Export)'!$B$28)*(1+'Assumptions (Export)'!$B$29)*(1+'Assumptions (Export)'!$B$30) -> 21.747798
A13: Skinless fillet — premium trim | B13: Inactive | C13: Fillet | D13: 0 | E13: 0.34 | F13: 1 | G13: 0 | H13: =F13+G13 -> 1 | I13: ='Assumptions (Export)'!$B$12 -> 2.5247059 | J13: =IFERROR(F13*I13/E13,0) -> 7.4256055 | K13: 0 | L13: =G13*K13 -> 0 | M13: =J13+L13 -> 7.4256055 | N13: 1.25 | O13: 0.35 | P13: ='Assumptions (Export)'!$B$18 -> 0.1 | Q13: =M13+N13+O13+P13 -> 9.1256055 | R13: ='Assumptions (Export)'!$B$17 -> 0.1 | S13: =Q13+R13 -> 9.2256055 | U13: =S13 -> 9.2256055 | V13: =IFERROR(S13/(1-'Assumptions (Export)'!$B$26),0) -> 15.376009 | W13: =V13+'Assumptions (Export)'!$B$36 -> 15.826009 | X13: =W13*(1+'Assumptions (Export)'!$B$28)*(1+'Assumptions (Export)'!$B$29)*(1+'Assumptions (Export)'!$B$30) -> 21.020897 | Y13: =S13-J13*D13/(1+D13) -> 9.2256055 | Z13: =IFERROR(Y13/(1-'Assumptions (Export)'!$B$26),0) -> 15.376009 | AA13: =Z13+'Assumptions (Export)'!$B$36 -> 15.826009 | AB13: =AA13*(1+'Assumptions (Export)'!$B$28)*(1+'Assumptions (Export)'!$B$29)*(1+'Assumptions (Export)'!$B$30) -> 21.020897 | AC13: =S13 -> 9.2256055 | AD13: =IFERROR(S13/(1-'Assumptions (Export)'!$B$26),0) -> 15.376009 | AE13: =AD13+'Assumptions (Export)'!$B$37 -> 18.176009 | AF13: =AE13*(1+'Assumptions (Export)'!$B$28)*(1+'Assumptions (Export)'!$B$29)*(1+'Assumptions (Export)'!$B$30) -> 24.142284
A14: Fillet portions — skin-on CC | B14: Active | C14: Fillet | D14: 0 | E14: 0.32 | F14: 1 | G14: 0 | H14: =F14+G14 -> 1 | I14: ='Assumptions (Export)'!$B$12 -> 2.5247059 | J14: =IFERROR(F14*I14/E14,0) -> 7.8897059 | K14: 0 | L14: =G14*K14 -> 0 | M14: =J14+L14 -> 7.8897059 | N14: 1.15 | O14: 0.35 | P14: ='Assumptions (Export)'!$B$18 -> 0.1 | Q14: =M14+N14+O14+P14 -> 9.4897059 | R14: ='Assumptions (Export)'!$B$17 -> 0.1 | S14: =Q14+R14 -> 9.5897059 | U14: =S14 -> 9.5897059 | V14: =IFERROR(S14/(1-'Assumptions (Export)'!$B$26),0) -> 15.982843 | W14: =V14+'Assumptions (Export)'!$B$36 -> 16.432843 | X14: =W14*(1+'Assumptions (Export)'!$B$28)*(1+'Assumptions (Export)'!$B$29)*(1+'Assumptions (Export)'!$B$30) -> 21.826924 | Y14: =S14-J14*D14/(1+D14) -> 9.5897059 | Z14: =IFERROR(Y14/(1-'Assumptions (Export)'!$B$26),0) -> 15.982843 | AA14: =Z14+'Assumptions (Export)'!$B$36 -> 16.432843 | AB14: =AA14*(1+'Assumptions (Export)'!$B$28)*(1+'Assumptions (Export)'!$B$29)*(1+'Assumptions (Export)'!$B$30) -> 21.826924 | AC14: =S14 -> 9.5897059 | AD14: =IFERROR(S14/(1-'Assumptions (Export)'!$B$26),0) -> 15.982843 | AE14: =AD14+'Assumptions (Export)'!$B$37 -> 18.782843 | AF14: =AE14*(1+'Assumptions (Export)'!$B$28)*(1+'Assumptions (Export)'!$B$29)*(1+'Assumptions (Export)'!$B$30) -> 24.948311
A15: Fillet portions — skinless | B15: Inactive | C15: Fillet | D15: 0 | E15: 0.36 | F15: 1 | G15: 0 | H15: =F15+G15 -> 1 | I15: ='Assumptions (Export)'!$B$12 -> 2.5247059 | J15: =IFERROR(F15*I15/E15,0) -> 7.0130719 | K15: 0 | L15: =G15*K15 -> 0 | M15: =J15+L15 -> 7.0130719 | N15: 1.15 | O15: 0.35 | P15: ='Assumptions (Export)'!$B$18 -> 0.1 | Q15: =M15+N15+O15+P15 -> 8.6130719 | R15: ='Assumptions (Export)'!$B$17 -> 0.1 | S15: =Q15+R15 -> 8.7130719 | U15: =S15 -> 8.7130719 | V15: =IFERROR(S15/(1-'Assumptions (Export)'!$B$26),0) -> 14.521786 | W15: =V15+'Assumptions (Export)'!$B$36 -> 14.971786 | X15: =W15*(1+'Assumptions (Export)'!$B$28)*(1+'Assumptions (Export)'!$B$29)*(1+'Assumptions (Export)'!$B$30) -> 19.886275 | Y15: =S15-J15*D15/(1+D15) -> 8.7130719 | Z15: =IFERROR(Y15/(1-'Assumptions (Export)'!$B$26),0) -> 14.521786 | AA15: =Z15+'Assumptions (Export)'!$B$36 -> 14.971786 | AB15: =AA15*(1+'Assumptions (Export)'!$B$28)*(1+'Assumptions (Export)'!$B$29)*(1+'Assumptions (Export)'!$B$30) -> 19.886275 | AC15: =S15 -> 8.7130719 | AD15: =IFERROR(S15/(1-'Assumptions (Export)'!$B$26),0) -> 14.521786 | AE15: =AD15+'Assumptions (Export)'!$B$37 -> 17.321786 | AF15: =AE15*(1+'Assumptions (Export)'!$B$28)*(1+'Assumptions (Export)'!$B$29)*(1+'Assumptions (Export)'!$B$30) -> 23.007663
... A37: Smoked fillet | B37: Inactive | C37: Value-added | D37: 0 | E37: 0.38 | F37: 0.95 | G37: 0.05 | H37: =F37+G37 -> 1 | I37: ='Assumptions (Export)'!$B$12 -> 2.5247059 | J37: =IFERROR(F37*I37/E37,0) -> 6.3117647 | K37: 1.5 | L37: =G37*K37 -> 0.075 | M37: =J37+L37 -> 6.3867647 | N37: 2.2 | O37: 0.6 | P37: ='Assumptions (Export)'!$B$18 -> 0.1 | Q37: =M37+N37+O37+P37 -> 9.2867647 | R37: ='Assumptions (Export)'!$B$17 -> 0.1 | S37: =Q37+R37 -> 9.3867647 | U37: =S37 -> 9.3867647 | V37: =IFERROR(S37/(1-'Assumptions (Export)'!$B$26),0) -> 15.644608 | W37: =V37+'Assumptions (Export)'!$B$36 -> 16.094608 | X37: =W37*(1+'Assumptions (Export)'!$B$28)*(1+'Assumptions (Export)'!$B$29)*(1+'Assumptions (Export)'!$B$30) -> 21.377663 | Y37: =S37-J37*D37/(1+D37) -> 9.3867647 | Z37: =IFERROR(Y37/(1-'Assumptions (Export)'!$B$26),0) -> 15.644608 | AA37: =Z37+'Assumptions (Export)'!$B$36 -> 16.094608 | AB37: =AA37*(1+'Assumptions (Export)'!$B$28)*(1+'Assumptions (Export)'!$B$29)*(1+'Assumptions (Export)'!$B$30) -> 21.377663 | AC37: =S37 -> 9.3867647 | AD37: =IFERROR(S37/(1-'Assumptions (Export)'!$B$26),0) -> 15.644608 | AE37: =AD37+'Assumptions (Export)'!$B$37 -> 18.444608 | AF37: =AE37*(1+'Assumptions (Export)'!$B$28)*(1+'Assumptions (Export)'!$B$29)*(1+'Assumptions (Export)'!$B$30) -> 24.49905
A39: Generic to FOB; CIF adds the SELECTED destination's freight (sea for frozen, air for fresh) from Assumptions (Export). Change the destination there to re-price all rows. Dist→T3 = CIF ×(1+clearing)×(1+imp)×(1+dist).

Sheet Master Yield summary 
C1: Fish Size | D1: 7374 Center Cuts | E1: TP 70-130 | F1: TP 40-70 | G1: Total | H1: Skin off Fillets | I1: Skin on Fillets | J1: S/O Regular Portions | K1: Boat Cut | L1: Butterfly Cut | M1: Skin on D-Trim | N1: GG | O1: Whole Round Gill Bled | P1: 7372 (F) 80/120g retail bag | Q1: 7370 ocean chef 3kg BTC | R1: 7364 Skinless 100/200 | S1: 7365 Skinless 200/300 | T1: 7366 Skinless 300/500 | U1: 7376 Skin On 200/300 | V1: 7377 Skin On 300/500 | W1: 7390 Skin On Costco 2KG bag | X1: KM Skin On 170/230 - 20% Glaze | Y1: KM Skin On 170/230 - 20% Glaze in pouch
C2: 500g | Q2: 0.38 | R2: 0.38
C3: 600g | Q3: 0.39 | R3: 0.39 | X3: =1*0.46*1.2 -> 0.552 | Y3: =1*0.46*1.2 -> 0.552
A4: 700 | C4: 700g | H4: 0.4 | I4: 0.44 | J4: =I4-1% -> 0.43 | K4: 0.7 | L4: 0.52 | N4: 0.88 | O4: 0.98 | Q4: 0.4 | R4: 0.4 | X4: =1*0.46*1.2 -> 0.552 | Y4: =1*0.46*1.2 -> 0.552
A5: 800 | C5: 800g | H5: 0.41 | I5: 0.45 | J5: =I5-1% -> 0.44 | K5: 0.7 | L5: 0.52 | N5: 0.88 | O5: 0.98 | P5: 0.45 | Q5: 0.4 | R5: 0.4 | U5: 0.47 | W5: 0.44
A6: 900 | C6: 900g | H6: 0.41 | I6: 0.45 | J6: =I6-1% -> 0.44 | K6: 0.7 | L6: 0.52 | N6: 0.88 | O6: 0.98 | P6: 0.46 | Q6: 0.41 | R6: 0.41 | U6: 0.47 | W6: 0.44
A7: 1000 | C7: 1kg | H7: 0.42 | I7: 0.46 | J7: =I7-1% -> 0.45 | K7: 0.7 | L7: 0.52 | N7: 0.88 | O7: 0.98 | P7: 0.47 | Q7: 0.42 | R7: 0.42 | U7: 0.48 | W7: 0.44
A8: 1100 | C8: 1.1kg | H8: 0.42 | I8: 0.46 | J8: =I8-1% -> 0.45 | K8: 0.7 | L8: 0.53 | N8: 0.88 | O8: 0.98 | P8: 0.48 | Q8: 0.42 | S8: 0.42 | U8: 0.48 | W8: 0.47
A9: 1200 | C9: 1.2kg | H9: 0.43 | I9: 0.48 | J9: =I9-1% -> 0.47 | K9: 0.7 | L9: 0.53 | M9: 0.43 | N9: 0.88 | O9: 0.98 | P9: 0.48 | Q9: 0.42 | S9: 0.42 | U9: 0.48 | W9: 0.48
A10: 1300 | C10: 1.3kg | H10: 0.43 | I10: 0.48 | J10: =I10-1% -> 0.47 | K10: 0.7 | L10: 0.53 | M10: 0.43 | N10: 0.88 | O10: 0.98 | P10: 0.48 | Q10: 0.42 | S10: 0.42 | U10: 0.48 | W10: 4.88
A11: 1400 | C11: 1.4kg | H11: 0.43 | I11: 0.48 | J11: =I11-1% -> 0.47 | K11: 0.7 | L11: 0.53 | M11: 0.43 | N11: 0.88 | O11: 0.98 | P11: 0.49 | Q11: 0.42 | S11: 0.42 | V11: 0.48 | W11: 0.48
A12: 1500 | C12: 1.5kg | H12: 0.43 | I12: 0.48 | J12: =I12-1% -> 0.47 | K12: 0.7 | L12: 0.53 | M12: 0.44 | N12: 0.88 | O12: 0.98 | P12: 0.49 | Q12: 0.42 | T12: 0.42 | V12: 0.48 | W12: 0.48
A13: 1600 | C13: 1.6kg | H13: 0.44 | I13: 0.49 | J13: =I13-1% -> 0.48 | K13: 0.7 | L13: 0.53 | M13: 0.44 | N13: 0.88 | O13: 0.98 | Q13: 0.43 | T13: 0.43 | V13: 0.49 | W13: 0.49
A14: 1700 | C14: 1.7kg | H14: 0.44 | I14: 0.49 | J14: =I14-1% -> 0.48 | K14: 0.7 | L14: 0.53 | M14: 0.44 | N14: 0.88 | O14: 0.98 | Q14: 0.43 | T14: 0.43 | V14: 0.49 | W14: 0.49
A15: 1800 | C15: 1.8kg | H15: 0.44 | I15: 0.49 | J15: =I15-1% -> 0.48 | K15: 0.7 | L15: 0.53 | M15: 0.44 | N15: 0.88 | O15: 0.98 | Q15: 0.44 | T15: 0.44 | V15: 0.49 | W15: 0.49
A16: 1900 | C16: 1.9kg | H16: 0.44 | I16: 0.49 | J16: =I16-1% -> 0.48 | K16: 0.7 | L16: 0.53 | M16: 0.44 | N16: 0.88 | O16: 0.98 | Q16: 0.44 | T16: 0.44 | V16: 0.5 | W16: 0.5
C17: 2.0kg | D17: 0.36 | E17: 0.08 | F17: 0 | G17: =SUM(D17:F17) -> 0.44 | H17: 0.45 | I17: 0.5 | J17: =I17-1% -> 0.49 | K17: 0.7 | L17: 0.54 | M17: 0.45 | N17: 0.88 | O17: 0.98 | Q17: 0.45 | T17: 0.45 | W17: 0.5
C18: 2.1kg | D18: 0.34 | E18: 0.09 | F18: 0 | G18: =SUM(D18:F18) -> 0.43 | H18: 0.45 | I18: 0.5 | J18: =I18-1% -> 0.49 | K18: 0.7 | L18: 0.54 | M18: 0.45 | N18: 0.88 | O18: 0.98 | T18: 0.45 | W18: 0.5
C19: 2.2kg | D19: 0.33 | E19: 0.1 | F19: 0 | G19: =SUM(D19:F19) -> 0.43 | H19: 0.45 | I19: 0.5 | J19: =I19-1% -> 0.49 | K19: 0.7 | L19: 0.54 | M19: 0.45 | N19: 0.88 | O19: 0.98 | T19: 0.45 | W19: 0.5
C20: 2.3kg | D20: 0.31 | E20: 0.11 | F20: 0 | G20: =SUM(D20:F20) -> 0.42 | H20: 0.45 | I20: 0.5 | J20: =I20-1% -> 0.49 | K20: 0.7 | L20: 0.54 | M20: 0.45 | N20: 0.88 | O20: 0.98 | T20: 0.45 | W20: 0.5
C21: 2.4kg | D21: 0.3 | E21: 0.1 | F21: 0.03 | G21: =SUM(D21:F21) -> 0.43 | H21: 0.45 | I21: 0.5 | J21: =I21-1% -> 0.49 | K21: 0.7 | L21: 0.54 | M21: 0.45 | N21: 0.88 | O21: 0.98 | T21: 0.45 | W21: 0.5
A22: 2000 | C22: 2.5kg | D22: 0.29 | E22: 0.1 | F22: 0.05 | G22: =SUM(D22:F22) -> 0.44 | H22: 0.45 | I22: 0.5 | J22: =I22-1% -> 0.49 | K22: 0.7 | L22: 0.54 | M22: 0.45 | N22: 0.88 | O22: 0.98 | T22: 0.45 | W22: 0.5
